<?xml version="1.0" ?>
<!--
 ...........       ____  _ __
 |  ,-^-,  |      / __ )(_) /_______________ _____  ___
 | (  O  ) |     / __  / / __/ ___/ ___/ __ `/_  / / _ \
 | / ,..´  |    / /_/ / / /_/ /__/ /  / /_/ / / /_/  __/
    +.......   /_____/_/\__/\___/_/   \__,_/ /___/\___/

MIT License

Copyright (c) 2022 Bitcraze
-->

<sdf version="1.8">
    <model name="crazyflie">
        <pose>0 0 0.0 0 0 3.14</pose>
        <link name="base_link">
            <inertial>
                <pose>0 0 0 0 0 0</pose>
                <mass>0.025</mass>
                <inertia>
                    <ixx>0.000016572</ixx>
                    <ixy>0.00</ixy>
                    <ixz>0.00</ixz>
                    <iyy>0.000016656</iyy>
                    <iyz>0.00000</iyz>
                    <izz>0.000029262</izz>
                </inertia>
            </inertial>
            <collision name="base_link/body_collision">
                <pose>0 0 0 0 0 0</pose>
                <geometry>
                    <box>
                        <size>0.10 0.10 0.03</size>
                    </box>
                </geometry>
            </collision>
            <visual name="base_link/body_visual">
                <pose>0 0 0 0 -0 0</pose>
                <geometry>
                    <mesh>
                        <scale>1 1 1</scale>
                        <uri>model://crazyflie/meshes/collada_files/cf2_assembly.dae</uri>
                    </mesh>
                </geometry>
            </visual>
            <sensor name="air_pressure_sensor" type="air_pressure">
                <always_on>1</always_on>
                <update_rate>50</update_rate>
                <air_pressure>
                <pressure>
                    <noise type="gaussian">
                    <mean>0</mean>
                    <stddev>0.01</stddev>
                    </noise>
                </pressure>
                </air_pressure>
            </sensor>
            <sensor name="imu_sensor" type="imu">
                <always_on>1</always_on>
                <update_rate>250</update_rate>
            </sensor>
        </link>
        <link name="rotor_0">
            <pose>0.031 -0.031 0.021 0 0 0</pose>
            <inertial>
                <pose>0 0 0 0 -0 0</pose>
                <mass>0.0008</mass>
                <inertia>
                    <ixx>0.000000002*70</ixx>
                    <iyy>0.000000167*70</iyy>
                    <izz>0.000000168*70</izz>
                    <ixy>0</ixy>
                    <ixz>0</ixz>
                    <iyz>0</iyz>
                </inertia>
            </inertial>
            <visual name="crazyflie/m1_visual">
                <pose>0 0 0 0 -0 0</pose>
                <geometry>
                    <mesh>
                        <scale>1 1 1</scale>
                        <uri>model://crazyflie/meshes/collada_files/ccw_prop.dae</uri>
                    </mesh>
                </geometry>
            </visual>
        </link>
        <link name="rotor_1">
            <pose >-0.031 0.031 0.021 0 0 0</pose>
            <inertial>
                <pose>0 0 0 0 -0 0</pose>
                <mass>0.0008</mass>
                <inertia>
                    <ixx>0.000000002*50</ixx>
                    <iyy>0.000000167*50</iyy>
                    <izz>0.000000168*50</izz>
                    <ixy>0</ixy>
                    <ixz>0</ixz>
                    <iyz>0</iyz>
                </inertia>
            </inertial>
            <visual name="crazyflie/m2_visual">
                <pose>0 0 0 0 -0 0</pose>
                <geometry>
                    <mesh>
                        <scale>1 1 1</scale>
                        <uri>model://crazyflie/meshes/collada_files/cw_prop.dae</uri>
                    </mesh>
                </geometry>
            </visual>
        </link>
        <link name="rotor_2">
            <pose>0.031 0.031 0.021 0 0 0</pose>
            <inertial>
                <pose>0 0 0 0 -0 0</pose>
                <mass>0.0008</mass>
                <inertia>
                    <ixx>0.000000002*50</ixx>
                    <iyy>0.000000167*50</iyy>
                    <izz>0.000000168*50</izz>
                    <ixy>0</ixy>
                    <ixz>0</ixz>
                    <iyz>0</iyz>
                </inertia>
            </inertial>
            <visual name="crazyflie/m3_visual">
                <pose>0 0 0 0 -0 0</pose>
                <geometry>
                    <mesh>
                        <scale>1 1 1</scale>
                        <uri>model://crazyflie/meshes/collada_files/ccw_prop.dae</uri>
                    </mesh>
                </geometry>
            </visual>
        </link>
        <link name="rotor_3">
            <pose>-0.031 -0.031 0.021 0 0 0</pose>
            <inertial>
                <pose>0 0 0 0 -0 0</pose>
                <mass>0.0008</mass>
                <inertia>
                    <ixx>0.000000002*50</ixx>
                    <iyy>0.000000167*50</iyy>
                    <izz>0.000000168*50</izz>
                    <ixy>0</ixy>
                    <ixz>0</ixz>
                    <iyz>0</iyz>
                </inertia>
            </inertial>
            <visual name="crazyflie/m4_visual">
                <pose>0 0 0 0 -0 0</pose>
                <geometry>
                    <mesh>
                        <scale>1 1 1</scale>
                        <uri>model://crazyflie/meshes/collada_files/cw_prop.dae</uri>
                    </mesh>
                </geometry>
            </visual>
        </link>
        <joint name="rotor_0_joint" type="revolute">
            <child>rotor_0</child>
            <parent>base_link</parent>
            <axis>
                <xyz>0 0 1</xyz>
                <limit>
                    <lower>-1e+16</lower>
                    <upper>1e+16</upper>
                </limit>
                <dynamics>
                    <spring_reference>0</spring_reference>
                    <spring_stiffness>0</spring_stiffness>
                </dynamics>
            </axis>
        </joint>
        <joint name="rotor_1_joint" type="revolute">
            <child>rotor_1</child>
            <parent>base_link</parent>
            <axis>
                <xyz>0 0 1</xyz>
                <limit>
                    <lower>-1e+16</lower>
                    <upper>1e+16</upper>
                </limit>
                <dynamics>
                    <spring_reference>0</spring_reference>
                    <spring_stiffness>0</spring_stiffness>
                </dynamics>
            </axis>
        </joint>
                <joint name="rotor_2_joint" type="revolute">
            <child>rotor_2</child>
            <parent>base_link</parent>
            <axis>
                <xyz>0 0 1</xyz>
                <limit>
                    <lower>-1e+16</lower>
                    <upper>1e+16</upper>
                </limit>
                <dynamics>
                    <spring_reference>0</spring_reference>
                    <spring_stiffness>0</spring_stiffness>
                </dynamics>
            </axis>
        </joint>
        <joint name="rotor_3_joint" type="revolute">
            <child>rotor_3</child>
            <parent>base_link</parent>
            <axis>
                <xyz>0 0 1</xyz>
                <limit>
                    <lower>-1e+16</lower>
                    <upper>1e+16</upper>
                </limit>
                <dynamics>
                    <spring_reference>0</spring_reference>
                    <spring_stiffness>0</spring_stiffness>
                </dynamics>
            </axis>
        </joint>
        <plugin filename="gz-sim-multicopter-motor-model-system" name="gz::sim::systems::MulticopterMotorModel">
            <jointName>rotor_0_joint</jointName>
            <linkName>rotor_0</linkName>
            <turningDirection>ccw</turningDirection>
            <timeConstantUp>0.0125</timeConstantUp>
            <timeConstantDown>0.025</timeConstantDown>
            <maxRotVelocity>1000.0</maxRotVelocity>
            <motorConstant>20.28192e-08</motorConstant>
            <momentConstant>0.005964552</momentConstant>
            <commandSubTopic>command/motor_speed</commandSubTopic>
            <motorNumber>0</motorNumber>
            <rotorDragCoefficient>8.06428e-05</rotorDragCoefficient>
            <rollingMomentCoefficient>1e-06</rollingMomentCoefficient>
            <rotorVelocitySlowdownSim>10</rotorVelocitySlowdownSim>
            <motorType>velocity</motorType>
        </plugin>
        <plugin filename="gz-sim-multicopter-motor-model-system" name="gz::sim::systems::MulticopterMotorModel">
            <jointName>rotor_1_joint</jointName>
            <linkName>rotor_1</linkName>
            <turningDirection>ccw</turningDirection>
            <timeConstantUp>0.0125</timeConstantUp>
            <timeConstantDown>0.025</timeConstantDown>
            <maxRotVelocity>1000.0</maxRotVelocity>
            <motorConstant>20.28192e-08</motorConstant>
            <momentConstant>0.005964552</momentConstant>
            <commandSubTopic>command/motor_speed</commandSubTopic>
            <motorNumber>1</motorNumber>
            <rotorDragCoefficient>8.06428e-05</rotorDragCoefficient>
            <rollingMomentCoefficient>1e-06</rollingMomentCoefficient>
            <rotorVelocitySlowdownSim>10</rotorVelocitySlowdownSim>
            <motorType>velocity</motorType>
        </plugin>
        <plugin filename="gz-sim-multicopter-motor-model-system" name="gz::sim::systems::MulticopterMotorModel">
            <jointName>rotor_2_joint</jointName>
            <linkName>rotor_2</linkName>
            <turningDirection>cw</turningDirection>
            <timeConstantUp>0.0125</timeConstantUp>
            <timeConstantDown>0.025</timeConstantDown>
            <maxRotVelocity>1000.0</maxRotVelocity>
            <motorConstant>20.28192e-08</motorConstant>
            <momentConstant>0.005964552</momentConstant>
            <commandSubTopic>command/motor_speed</commandSubTopic>
            <motorNumber>2</motorNumber>
            <rotorDragCoefficient>8.06428e-05</rotorDragCoefficient>
            <rollingMomentCoefficient>1e-06</rollingMomentCoefficient>
            <rotorVelocitySlowdownSim>10</rotorVelocitySlowdownSim>
            <motorType>velocity</motorType>
        </plugin>
        <plugin filename="gz-sim-multicopter-motor-model-system" name="gz::sim::systems::MulticopterMotorModel">
            <jointName>rotor_3_joint</jointName>
            <linkName>rotor_3</linkName>
            <turningDirection>cw</turningDirection>
            <timeConstantUp>0.0125</timeConstantUp>
            <timeConstantDown>0.025</timeConstantDown>
            <maxRotVelocity>1000.0</maxRotVelocity>
            <motorConstant>20.28192e-08</motorConstant>
            <momentConstant>0.005964552</momentConstant>
            <commandSubTopic>command/motor_speed</commandSubTopic>
            <motorNumber>3</motorNumber>
            <rotorDragCoefficient>8.06428e-05</rotorDragCoefficient>
            <rollingMomentCoefficient>1e-06</rollingMomentCoefficient>
            <rotorVelocitySlowdownSim>10</rotorVelocitySlowdownSim>
            <motorType>velocity</motorType>
        </plugin>
        <plugin filename="ignition-gazebo-odometry-publisher-system" name="ignition::gazebo::systems::OdometryPublisher">
            <dimensions>3</dimensions>
        </plugin>
    </model>
</sdf>
